Workbook

Sheet Strategy comparison
B2: ST Capital Gains | E2: Strategy Comparison
F3: No Planning | G3: Film | H3: Solar | I3: LCD | J3: Solar & Charitable | K3: LEAP | L3: LEAP & Charitable
B4: Filing Status | C4: Married-Joint | E4: Fed Ordinary Income Tax | F4: ='No planning'!C19 -> 81195.42 | G4: =Film!C22 -> 11599.88 | H4: =MIN(Solar!C20, F4) -> 0 | I4: =Charitable!C22 -> 33423.66 | J4: =MIN('Solar & Charitable'!C25,'Solar & Charitable'!C58) -> 0 | K4: =LEAP!C28 -> 113167.1 | L4: ='LEAP & Charitable'!C63 -> 33423.66
B5: W2 | C5: 400000 | E5: Fed LTCG Tax | F5: ='No planning'!C20 -> 0 | G5: =Film!C24 -> 0 | H5: =MIN(MAX(Solar!C20 - H4, 0), F5) -> 0 | I5: =Charitable!C24 -> 0 | J5: =MIN(MAX('Solar & Charitable'!C58-'Strategy comparison'!J4,0),'Solar & Charitable'!C27) -> 0 | K5: =LEAP!J28 -> 0 | L5: ='LEAP & Charitable'!C65 -> 0
B6: Business Income | E6: State Tax | F6: ='No planning'!I42 -> 12000 | G6: =Film!I42 -> 3024 | H6: =Solar!J42 -> 11058.167 | I6: =Charitable!H42 -> 12000 | J6: ='Solar & Charitable'!J42 -> 11017.89 | K6: =LEAP!C29 -> 12000 | L6: ='LEAP & Charitable'!C64 -> 12000
B7: ST Capital Gains | E7: Strategy Contribution | F7: 0 | G7: =Film!D14 -> 62989.474 | H7: =Solar!C18 -> 70591.824 | I7: =Charitable!D14 -> 40000 | J7: ='Solar & Charitable'!D17+'Solar & Charitable'!C49 -> 73022.32 | K7: =LEAP!D14+LEAP!E14+LEAP!D12+LEAP!E12 -> -17640 | L7: ='LEAP & Charitable'!C78-L9 -> 40000
B8: LT Capital Gains | E8: Investment Account | F8: 0 | G8: 0 | H8: 0 | I8: 0 | J8: 0 | K8: =LEAP!D20+LEAP!E20 -> -7560 | L8: ='LEAP & Charitable'!C79 -> 0
B9: Interest | E9: Membership Fee | F9: 0 | G9: =Film!D16 -> 0 | H9: =C12 -> 0 | I9: =C12 -> 0 | J9: =C12 -> 0 | K9: =C12 -> 0 | L9: =C12 -> 0
B10: Qualified Dividends | E10: Total Cash Outlay | F10: =SUM(F4:F9) -> 93195.42 | G10: =SUM(G4:G9) -> 77613.354 | H10: =SUM(H4:H9) -> 81649.991 | I10: =SUM(I4:I9) -> 85423.66 | J10: =SUM(J4:J9) -> 84040.21 | K10: =SUM(K4:K7)+K9 -> 107527.1 | L10: =SUM(L4:L9) -> 85423.66
B11: Nonqualified Dividends | E11: Savings | F11: 0 | G11: =$F10-G10 -> 15582.066 | H11: =$F10-H10 -> 11545.429 | I11: =$F10-I10 -> 7771.76 | J11: =$F10-J10 -> 9155.2102 | K11: =$F10-K10 -> -14331.68 | L11: =F10-L10+L8 -> 7771.76
B12: Consulting Fee | E12: Effective Tax Rate | F12: =($F$10-F11)/'No planning'!$C$15 -> 0.23298855 | G12: =($F$10-G11)/'No planning'!$C$15 -> 0.19403338 | H12: =($F$10-H11)/'No planning'!$C$15 -> 0.20412498 | I12: =($F$10-I11)/'No planning'!$C$15 -> 0.21355915 | J12: =($F$10-J11)/'No planning'!$C$15 -> 0.21010052 | K12: =K10/'No planning'!$C$15 -> 0.26881775 | L12: =($F$10-L11)/'No planning'!$C$15 -> 0.21355915
G15: Manual Inputs
G16: Film | H16: Solar | I16: Charitable | J16: Solar & Charitable | K16: LEAP | L16: LEAP & Charitable
G17: Income Offset | H17: Equity Contribution | I17: Charitable Donation | J17: Charitable Donation | K17: SOP NEG K1 - Biz. Income | L17: SOP NEG K1 - Biz. Income
G18: =SUM(C5:C11)-100800 -> 299200 | K18: =C6-100800 -> -100800
J19: Equity Contribution | K19: SOP NEG K1 - LTCG | L19: SOP NEG K1 - LTCG
L21: Charitable Donation

Sheet DB comparison
B2: DB Contribution | G2: Manual Inputs
G3: Film & DB | H3: Solar & DB | I3: Charitable & DB | J3: Solar & Charitable & DB | K3: LEAP & DB | L3: LEAP & Charitable & DB
G4: Income Offset | H4: Equity Contribution | I4: Charitable Donation | J4: Charitable Donation | K4: SOP NEG K1 - Biz. Income | L4: SOP NEG K1 - Biz. Income
J6: Equity Contribution | K6: SOP NEG K1 - LTCG | L6: SOP NEG K1 - LTCG
L8: Charitable Donation
E11: No DB Contribution
F12: No Planning | G12: Film | H12: Solar | I12: Charitable | J12: Solar & Charitable | K12: LEAP | L12: LEAP & Charitable
E13: Fed Ordinary Income Tax | F13: ='No planning'!C19 -> 81195.42 | G13: =Film!C22 -> 11599.88 | H13: =MIN(Solar!C20, F13) -> 0 | I13: =Charitable!C22 -> 33423.66 | J13: =MIN('Solar & Charitable'!C25,'Solar & Charitable'!C58) -> 0 | K13: =LEAP!C28 -> 113167.1 | L13: ='LEAP & Charitable'!C63 -> 33423.66
E14: Fed LTCG Tax | F14: ='No planning'!C20 -> 0 | G14: =Film!C24 -> 0 | H14: =MIN(MAX(Solar!C20 - H13, 0), F14) -> 0 | I14: =Charitable!C24 -> 0 | J14: =MIN(MAX('Solar & Charitable'!C58-'Strategy comparison'!J4,0),'Solar & Charitable'!C27) -> 0 | K14: =LEAP!J28 -> 0 | L14: ='LEAP & Charitable'!C65 -> 0
E15: State Tax | F15: ='No planning'!I42 -> 12000 | G15: =Film!I42 -> 3024 | H15: =Solar!J42 -> 11059.732 | I15: =Charitable!H42 -> 12000 | J15: ='Solar & Charitable'!J42 -> 11017.77 | K15: =LEAP!C29 -> 12000 | L15: ='LEAP & Charitable'!C64 -> 12000
E16: Strategy Contribution | F16: 0 | G16: =Film!D14 -> 62989.474 | H16: =Solar!C18 -> 70583.134 | I16: =Charitable!D14 -> 40000 | J16: ='Solar & Charitable'!D17+'Solar & Charitable'!C49 -> 73013.342 | K16: =LEAP!D14+LEAP!E14+LEAP!D12+LEAP!E12 -> -17640 | L16: ='LEAP & Charitable'!C78-L18 -> 40000
E17: Investment Account | F17: 0 | G17: 0 | H17: 0 | I17: 0 | J17: 0 | K17: =LEAP!D20+LEAP!E20 -> -7560 | L17: ='LEAP & Charitable'!C79 -> 0
E18: Membership Fee | F18: 0 | G18: ='Strategy comparison'!$C$12 -> 0 | H18: ='Strategy comparison'!$C$12 -> 0 | I18: ='Strategy comparison'!$C$12 -> 0 | J18: ='Strategy comparison'!$C$12 -> 0 | K18: ='Strategy comparison'!$C$12 -> 0 | L18: ='Strategy comparison'!$C$12 -> 0
E19: Total Cash Outlay | F19: =SUM(F13:F18) -> 93195.42 | G19: =SUM(G13:G18) -> 77613.354 | H19: =SUM(H13:H18) -> 81642.866 | I19: =SUM(I13:I18) -> 85423.66 | J19: =SUM(J13:J18) -> 84031.112 | K19: =SUM(K13:K18) -> 99967.1 | L19: =SUM(L13:L18) -> 85423.66
E20: Savings | F20: 0 | G20: =$F19-G19 -> 15582.066 | H20: =$F19-H19 -> 11552.554 | I20: =$F19-I19 -> 7771.76 | J20: =$F19-J19 -> 9164.3082 | K20: =$F19-K19+K17 -> -14331.68 | L20: =F19-L19+L17 -> 7771.76
E21: Effective Tax Rate | F21: =($F$19-F20)/'No planning'!$C$15 -> 0.23298855 | G21: =($F$19-G20)/'No planning'!$C$15 -> 0.19403338 | H21: =($F$19-H20)/'No planning'!$C$15 -> 0.20410716 | I21: =($F$19-I20)/'No planning'!$C$15 -> 0.21355915 | J21: =($F$19-J20)/'No planning'!$C$15 -> 0.21007778 | K21: =($F$19-K20)/'No planning'!$C$15 -> 0.26881775 | L21: =($F$19-L20)/'No planning'!$C$15 -> 0.21355915
E23: DB Contribution
F24: DB Only | G24: Film & DB | H24: Solar & DB | I24: Charitable & DB | J24: Solar & Charitable & DB | K24: LEAP & DB | L24: LEAP & Charitable & DB
E25: DB Contribution | F25: ='DB comparison'!$C$2 -> 0 | G25: ='DB comparison'!$C$2 -> 0 | H25: ='DB comparison'!$C$2 -> 0 | I25: ='DB comparison'!$C$2 -> 0 | J25: ='DB comparison'!$C$2 -> 0 | K25: ='DB comparison'!$C$2 -> 0 | L25: ='DB comparison'!$C$2 -> 0
E26: Fed Ordinary Income Tax | F26: ='DB Only'!C14 -> 81195.42 | G26: ='Film & DB'!C22 -> 0 | H26: =MIN('Solar & DB'!C20, F26) -> 0 | I26: ='Charitable & DB'!C22 -> 33423.66 | J26: =MIN('Solar & Charitable & DB'!C25,'Solar & Charitable & DB'!C58) -> 0 | K26: ='LEAP & DB'!C28 -> 81195.42 | L26: ='LEAP & Charitable & DB'!C63 -> 33423.66
E27: Fed LTCG Tax | F27: ='DB Only'!C15 -> 0 | G27: ='Film & DB'!C24 -> 0 | H27: =MIN(MAX('Solar & DB'!C20 - H26, 0), F27) -> 0 | I27: ='Charitable & DB'!C24 -> 0 | J27: =MIN(MAX('Solar & Charitable & DB'!C58-'DB comparison'!J26,0),'Solar & Charitable & DB'!C27) -> 0 | K27: ='LEAP & DB'!C30 -> 0 | L27: ='LEAP & Charitable & DB'!C65 -> 0
E28: State Tax | F28: ='DB Only'!C16 -> 12000 | G28: ='Film & DB'!C23 -> 0 | H28: ='Solar & DB'!J42 -> 11059.732 | I28: ='Charitable & DB'!C23 -> 12000 | J28: ='Solar & Charitable & DB'!J42 -> 11017.796 | K28: ='LEAP & DB'!J42 -> 12000 | L28: ='LEAP & Charitable & DB'!C64 -> 12000
E29: Strategy Contribution | F29: 0 | G29: ='Film & DB'!D14 -> 84210.526 | H29: ='Solar & DB'!C18 -> 70583.134 | I29: ='Charitable & DB'!D14 -> 40000 | J29: ='Solar & Charitable & DB'!D17+'Solar & Charitable & DB'!C49 -> 73029.372 | K29: ='LEAP & DB'!D14+'LEAP & DB'!E14+'LEAP & DB'!D12+'LEAP & DB'!E12 -> 0 | L29: ='LEAP & Charitable & DB'!C78-L31 -> 40000
E30: Investment Account | F30: 0 | G30: 0 | H30: 0 | I30: 0 | J30: 0 | K30: ='LEAP & DB'!D20+'LEAP & DB'!E20 -> 0 | L30: ='LEAP & Charitable & DB'!C79 -> 0
E31: Planning Fee | F31: ='Strategy comparison'!$C$12 -> 0 | G31: ='Strategy comparison'!$C$12 -> 0 | H31: ='Strategy comparison'!$C$12 -> 0 | I31: ='Strategy comparison'!$C$12 -> 0 | J31: ='Strategy comparison'!$C$12 -> 0 | K31: ='Strategy comparison'!$C$12 -> 0 | L31: ='Strategy comparison'!$C$12 -> 0
E32: Total Cash Outlay | F32: =SUM(F25:F31) -> 93195.42 | G32: =SUM(G25:G31) -> 84210.526 | H32: =SUM(H25:H31) -> 81642.866 | I32: =SUM(I25:I31) -> 85423.66 | J32: =SUM(J25:J31) -> 84047.168 | K32: =SUM(K25:K31) -> 93195.42 | L32: =SUM(L25:L31) -> 85423.66
E33: Savings | F33: ='Strategy comparison'!$F$10-F32+F25+F30 -> 0 | G33: ='Strategy comparison'!$F$10-G32+G25+G30 -> 8984.8937 | H33: ='Strategy comparison'!$F$10-H32+H25+H30 -> 11552.554 | I33: ='Strategy comparison'!$F$10-I32+I25+I30 -> 7771.76 | J33: ='Strategy comparison'!$F$10-J32+J25+J30 -> 9148.2522 | K33: ='Strategy comparison'!$F$10-K32+K25+K30 -> 0 | L33: ='Strategy comparison'!$F$10-L32+L25+L30 -> 7771.76
E34: Effective Tax Rate | F34: =('Strategy comparison'!$F$10-F33)/'No planning'!$C$15 -> 0.23298855 | G34: =('Strategy comparison'!$F$10-G33)/'No planning'!$C$15 -> 0.21052632 | H34: =('Strategy comparison'!$F$10-H33)/'No planning'!$C$15 -> 0.20410716 | I34: =('Strategy comparison'!$F$10-I33)/'No planning'!$C$15 -> 0.21355915 | J34: =('Strategy comparison'!$F$10-J33)/'No planning'!$C$15 -> 0.21011792 | K34: =('Strategy comparison'!$F$10-K33)/'No planning'!$C$15 -> 0.23298855 | L34: =('Strategy comparison'!$F$10-L33)/'No planning'!$C$15 -> 0.21355915
E36: Net Savings
F37: No Strategy | G37: Film | H37: Solar | I37: Charitable | J37: Solar & Charitable | K37: LEAP | L37: LEAP & Charitable
E38: No DB Plan | F38: ='Strategy comparison'!F11 -> 0 | G38: ='Strategy comparison'!G11 -> 15582.066 | H38: ='Strategy comparison'!H11 -> 11552.554 | I38: ='Strategy comparison'!I11 -> 7771.76 | J38: ='Strategy comparison'!J11 -> 9164.3082 | K38: ='Strategy comparison'!K11 -> -14331.68 | L38: ='Strategy comparison'!L11 -> 7771.76
E39: DB Plan | F39: ='DB comparison'!F33 -> 0 | G39: ='DB comparison'!G33 -> 8984.8937 | H39: ='DB comparison'!H33 -> 11552.554 | I39: ='DB comparison'!I33 -> 7771.76 | J39: ='DB comparison'!J33 -> 9148.2522 | K39: ='DB comparison'!K33 -> 0 | L39: ='DB comparison'!L33 -> 7771.76
E41: Effective Tax Rate
F42: No Strategy | G42: Film | H42: Solar | I42: Charitable | J42: Solar & Charitable | K42: LEAP | L42: LEAP & Charitable
E43: No DB Plan | F43: ='Strategy comparison'!F12 -> 0.23298855 | G43: ='Strategy comparison'!G12 -> 0.19403338 | H43: ='Strategy comparison'!H12 -> 0.20410716 | I43: ='Strategy comparison'!I12 -> 0.21355915 | J43: ='Strategy comparison'!J12 -> 0.21007778 | K43: ='Strategy comparison'!K12 -> 0.26881775 | L43: ='Strategy comparison'!L12 -> 0.21355915
E44: DB Plan | F44: ='DB comparison'!F34 -> 0.23298855 | G44: ='DB comparison'!G34 -> 0.21052632 | H44: ='DB comparison'!H34 -> 0.20410716 | I44: ='DB comparison'!I34 -> 0.21355915 | J44: ='DB comparison'!J34 -> 0.21011792 | K44: ='DB comparison'!K34 -> 0.23298855 | L44: ='DB comparison'!L34 -> 0.21355915

Sheet Roth comparison
S1: Age | T1: Roth IRA (Post Strategy) Income | U1: Roth IRA (No Strategy) Income | V1: Traditional IRA Income
B2: Roth conversion amount | C2: 450000 | G2: Manual Inputs | N2: Roth Conversion Tax w/ Savings | O2: Roth conversion tax | P2: PV Traditional IRA RMD Tax | S2: =C3 -> 65 | T2: =IFERROR(_xlfn.XLOOKUP(S2,'RMD Simulation'!AL:AL,'RMD Simulation'!AS:AS),"") -> 13235.941 | U2: =IFERROR(_xlfn.XLOOKUP(S2,'RMD Simulation'!AA:AA,'RMD Simulation'!AH:AH),"") -> 11241.302 | V2: =IFERROR(_xlfn.XLOOKUP(S2,'RMD Simulation'!P:P,'RMD Simulation'!W:W),"") -> 11700
B3: Current Age | C3: 65 | G3: Film & Roth | H3: Solar & Roth | I3: Charitable & Roth | J3: Solar & Charitable & Roth | K3: LEAP & Roth | L3: LEAP & Charitable & Roth | N3: =O3-C13 -> 119101.47 | O3: ='RMD Simulation'!B14 -> 168967.46 | P3: ='RMD Simulation'!B22 -> 151200 | S3: =IFERROR(IF(S2+1>99,"",S2+1),"") -> 66 | T3: =IFERROR(_xlfn.XLOOKUP(S3,'RMD Simulation'!AL:AL,'RMD Simulation'!AS:AS),"") -> 13595.959 | U3: =IFERROR(_xlfn.XLOOKUP(S3,'RMD Simulation'!AA:AA,'RMD Simulation'!AH:AH),"") -> 11547.065 | V3: =IFERROR(_xlfn.XLOOKUP(S3,'RMD Simulation'!P:P,'RMD Simulation'!W:W),"") -> 12018.24
B4: Retirement age | C4: 65 | G4: Income Offset | H4: Equity Contribution | I4: Charitable Donation | J4: Charitable Donation | K4: SOP NEG K1 - Biz. Income | L4: SOP NEG K1 - Biz. Income | N4: Roth IRA (Post Strategy) at 100 | O4: Roth IRA (No Strategy) at 100 | P4: Traditional IRA at 100 (post tax) | S4: =IFERROR(IF(S3+1>99,"",S3+1),"") -> 67 | T4: =IFERROR(_xlfn.XLOOKUP(S4,'RMD Simulation'!AL:AL,'RMD Simulation'!AS:AS),"") -> 13965.769 | U4: =IFERROR(_xlfn.XLOOKUP(S4,'RMD Simulation'!AA:AA,'RMD Simulation'!AH:AH),"") -> 11861.145 | V4: =IFERROR(_xlfn.XLOOKUP(S4,'RMD Simulation'!P:P,'RMD Simulation'!W:W),"") -> 12345.136
B5: Minimum withdrawal rate | C5: 0.04 | N5: ='RMD Simulation'!AO68 -> 304538.76 | O5: ='RMD Simulation'!AH68 -> 258645.16 | P5: ='RMD Simulation'!W68 -> 269199.1 | S5: =IFERROR(IF(S4+1>99,"",S4+1),"") -> 68 | T5: =IFERROR(_xlfn.XLOOKUP(S5,'RMD Simulation'!AL:AL,'RMD Simulation'!AS:AS),"") -> 14345.638 | U5: =IFERROR(_xlfn.XLOOKUP(S5,'RMD Simulation'!AA:AA,'RMD Simulation'!AH:AH),"") -> 12183.768 | V5: =IFERROR(_xlfn.XLOOKUP(S5,'RMD Simulation'!P:P,'RMD Simulation'!W:W),"") -> 12680.924
B6: Current tax rate (federal + state) | C6: ='RMD Simulation'!B15 -> 0.37548324 | J6: Equity Contribution | K6: SOP NEG K1 - LTCG | L6: SOP NEG K1 - LTCG | S6: =IFERROR(IF(S5+1>99,"",S5+1),"") -> 69 | T6: =IFERROR(_xlfn.XLOOKUP(S6,'RMD Simulation'!AL:AL,'RMD Simulation'!AS:AS),"") -> 14735.839 | U6: =IFERROR(_xlfn.XLOOKUP(S6,'RMD Simulation'!AA:AA,'RMD Simulation'!AH:AH),"") -> 12515.167 | V6: =IFERROR(_xlfn.XLOOKUP(S6,'RMD Simulation'!P:P,'RMD Simulation'!W:W),"") -> 13025.845
B7: Input: Projected tax rate (federal + state) | C7: 0.35 | S7: =IFERROR(IF(S6+1>99,"",S6+1),"") -> 70 | T7: =IFERROR(_xlfn.XLOOKUP(S7,'RMD Simulation'!AL:AL,'RMD Simulation'!AS:AS),"") -> 15136.654 | U7: =IFERROR(_xlfn.XLOOKUP(S7,'RMD Simulation'!AA:AA,'RMD Simulation'!AH:AH),"") -> 12855.579 | V7: =IFERROR(_xlfn.XLOOKUP(S7,'RMD Simulation'!P:P,'RMD Simulation'!W:W),"") -> 13380.148
B8: Projected tax rate (federal + state) | C8: =IF(C7="",C6,C7) -> 0.35 | L8: Charitable Donation | S8: =IFERROR(IF(S7+1>99,"",S7+1),"") -> 71 | T8: =IFERROR(_xlfn.XLOOKUP(S8,'RMD Simulation'!AL:AL,'RMD Simulation'!AS:AS),"") -> 15548.371 | U8: =IFERROR(_xlfn.XLOOKUP(S8,'RMD Simulation'!AA:AA,'RMD Simulation'!AH:AH),"") -> 13205.251 | V8: =IFERROR(_xlfn.XLOOKUP(S8,'RMD Simulation'!P:P,'RMD Simulation'!W:W),"") -> 13744.088
B9: Discount rate | C9: 0.07 | S9: =IFERROR(IF(S8+1>99,"",S8+1),"") -> 72 | T9: =IFERROR(_xlfn.XLOOKUP(S9,'RMD Simulation'!AL:AL,'RMD Simulation'!AS:AS),"") -> 15971.286 | U9: =IFERROR(_xlfn.XLOOKUP(S9,'RMD Simulation'!AA:AA,'RMD Simulation'!AH:AH),"") -> 13564.434 | V9: =IFERROR(_xlfn.XLOOKUP(S9,'RMD Simulation'!P:P,'RMD Simulation'!W:W),"") -> 14117.927
S10: =IFERROR(IF(S9+1>99,"",S9+1),"") -> 73 | T10: =IFERROR(_xlfn.XLOOKUP(S10,'RMD Simulation'!AL:AL,'RMD Simulation'!AS:AS),"") -> 16405.705 | U10: =IFERROR(_xlfn.XLOOKUP(S10,'RMD Simulation'!AA:AA,'RMD Simulation'!AH:AH),"") -> 13933.387 | V10: =IFERROR(_xlfn.XLOOKUP(S10,'RMD Simulation'!P:P,'RMD Simulation'!W:W),"") -> 14501.935
B11: Strategy Input | E11: RMD (No conversion) | S11: =IFERROR(IF(S10+1>99,"",S10+1),"") -> 74 | T11: =IFERROR(_xlfn.XLOOKUP(S11,'RMD Simulation'!AL:AL,'RMD Simulation'!AS:AS),"") -> 16851.941 | U11: =IFERROR(_xlfn.XLOOKUP(S11,'RMD Simulation'!AA:AA,'RMD Simulation'!AH:AH),"") -> 14312.375 | V11: =IFERROR(_xlfn.XLOOKUP(S11,'RMD Simulation'!P:P,'RMD Simulation'!W:W),"") -> 14896.387
B12: Strategy Used | C12: =IF(C11="",_xlfn.XLOOKUP(MAX(F42:L42),F42:L42,F40:L40),C11) -> Film | F12: No Planning | G12: Film | H12: Solar | I12: Charitable | J12: Solar & Charitable | K12: LEAP | L12: LEAP & Charitable | S12: =IFERROR(IF(S11+1>99,"",S11+1),"") -> 75 | T12: =IFERROR(_xlfn.XLOOKUP(S12,'RMD Simulation'!AL:AL,'RMD Simulation'!AS:AS),"") -> 17591.782 | U12: =IFERROR(_xlfn.XLOOKUP(S12,'RMD Simulation'!AA:AA,'RMD Simulation'!AH:AH),"") -> 14940.723 | V12: =IFERROR(_xlfn.XLOOKUP(S12,'RMD Simulation'!P:P,'RMD Simulation'!W:W),"") -> 15550.375
B13: Savings | C13: =_xlfn.XLOOKUP(C12,F40:L40,F43:L43) -> 49865.985 | E13: Fed Ordinary Income Tax | F13: ='No planning'!C19 -> 81195.42 | G13: =Film!C22 -> 11599.88 | H13: =MIN(Solar!C20, F13) -> 0 | I13: =Charitable!C22 -> 33423.66 | J13: =MIN('Solar & Charitable'!C25,'Solar & Charitable'!C58) -> 0 | K13: =LEAP!C28 -> 113167.1 | L13: ='LEAP & Charitable'!C63 -> 33423.66 | S13: =IFERROR(IF(S12+1>99,"",S12+1),"") -> 76 | T13: =IFERROR(_xlfn.XLOOKUP(S13,'RMD Simulation'!AL:AL,'RMD Simulation'!AS:AS),"") -> 18743.784 | U13: =IFERROR(_xlfn.XLOOKUP(S13,'RMD Simulation'!AA:AA,'RMD Simulation'!AH:AH),"") -> 15919.12 | V13: =IFERROR(_xlfn.XLOOKUP(S13,'RMD Simulation'!P:P,'RMD Simulation'!W:W),"") -> 16568.695
E14: PV RMD Tax | F14: ='RMD Simulation'!$B$22 -> 151200 | G14: ='RMD Simulation'!$B$22 -> 151200 | H14: ='RMD Simulation'!$B$22 -> 151200 | I14: ='RMD Simulation'!$B$22 -> 151200 | J14: ='RMD Simulation'!$B$22 -> 151200 | K14: ='RMD Simulation'!$B$22 -> 151200 | L14: ='RMD Simulation'!$B$22 -> 151200 | S14: =IFERROR(IF(S13+1>99,"",S13+1),"") -> 77 | T14: =IFERROR(_xlfn.XLOOKUP(S14,'RMD Simulation'!AL:AL,'RMD Simulation'!AS:AS),"") -> 19880.688 | U14: =IFERROR(_xlfn.XLOOKUP(S14,'RMD Simulation'!AA:AA,'RMD Simulation'!AH:AH),"") -> 16884.694 | V14: =IFERROR(_xlfn.XLOOKUP(S14,'RMD Simulation'!P:P,'RMD Simulation'!W:W),"") -> 17573.67
E15: Fed LTCG Tax | F15: ='No planning'!C20 -> 0 | G15: =Film!C24 -> 0 | H15: =MIN(MAX(Solar!C20 - H13, 0), F15) -> 0 | I15: =Charitable!C24 -> 0 | J15: =MIN(MAX('Solar & Charitable'!C58-J13,0),'Solar & Charitable'!C27) -> 0 | K15: =LEAP!J28 -> 0 | L15: ='LEAP & Charitable'!C65 -> 0 | S15: =IFERROR(IF(S14+1>99,"",S14+1),"") -> 78 | T15: =IFERROR(_xlfn.XLOOKUP(S15,'RMD Simulation'!AL:AL,'RMD Simulation'!AS:AS),"") -> 21175.644 | U15: =IFERROR(_xlfn.XLOOKUP(S15,'RMD Simulation'!AA:AA,'RMD Simulation'!AH:AH),"") -> 17984.502 | V15: =IFERROR(_xlfn.XLOOKUP(S15,'RMD Simulation'!P:P,'RMD Simulation'!W:W),"") -> 18718.355
E16: State Tax | F16: ='No planning'!I42 -> 12000 | G16: =Film!I42 -> 3024 | H16: =Solar!J42 -> 11059.732 | I16: =Charitable!H42 -> 12000 | J16: ='Solar & Charitable'!J42 -> 11017.77 | K16: =LEAP!C29 -> 12000 | L16: ='LEAP & Charitable'!C64 -> 12000 | S16: =IFERROR(IF(S15+1>99,"",S15+1),"") -> 79 | T16: =IFERROR(_xlfn.XLOOKUP(S16,'RMD Simulation'!AL:AL,'RMD Simulation'!AS:AS),"") -> 22550.556 | U16: =IFERROR(_xlfn.XLOOKUP(S16,'RMD Simulation'!AA:AA,'RMD Simulation'!AH:AH),"") -> 19152.216 | V16: =IFERROR(_xlfn.XLOOKUP(S16,'RMD Simulation'!P:P,'RMD Simulation'!W:W),"") -> 19933.717
E17: Strategy Contribution | F17: 0 | G17: =Film!D14 -> 62989.474 | H17: =Solar!C18 -> 70583.134 | I17: =Charitable!D14 -> 40000 | J17: ='Solar & Charitable'!D17+'Solar & Charitable'!C49 -> 73013.342 | K17: =LEAP!D14+LEAP!E14+LEAP!D12+LEAP!E12 -> -17640 | L17: ='LEAP & Charitable'!C78-L19 -> 40000 | S17: =IFERROR(IF(S16+1>99,"",S16+1),"") -> 80 | T17: =IFERROR(_xlfn.XLOOKUP(S17,'RMD Simulation'!AL:AL,'RMD Simulation'!AS:AS),"") -> 24009.644 | U17: =IFERROR(_xlfn.XLOOKUP(S17,'RMD Simulation'!AA:AA,'RMD Simulation'!AH:AH),"") -> 20391.421 | V17: =IFERROR(_xlfn.XLOOKUP(S17,'RMD Simulation'!P:P,'RMD Simulation'!W:W),"") -> 21223.488
E18: Investment Account | F18: 0 | G18: 0 | H18: 0 | I18: 0 | J18: 0 | K18: =LEAP!D20+LEAP!E20 -> -7560 | L18: ='LEAP & Charitable'!C79 -> 0 | S18: =IFERROR(IF(S17+1>99,"",S17+1),"") -> 81 | T18: =IFERROR(_xlfn.XLOOKUP(S18,'RMD Simulation'!AL:AL,'RMD Simulation'!AS:AS),"") -> 25425.47 | U18: =IFERROR(_xlfn.XLOOKUP(S18,'RMD Simulation'!AA:AA,'RMD Simulation'!AH:AH),"") -> 21593.884 | V18: =IFERROR(_xlfn.XLOOKUP(S18,'RMD Simulation'!P:P,'RMD Simulation'!W:W),"") -> 22475.017
E19: Membership Fee | F19: 0 | G19: =Film!D16 -> 0 | H19: ='Strategy comparison'!C12 -> 0 | I19: ='Strategy comparison'!C12 -> 0 | J19: ='Strategy comparison'!C12 -> 0 | K19: ='Strategy comparison'!C12 -> 0 | L19: ='Strategy comparison'!C12 -> 0 | S19: =IFERROR(IF(S18+1>99,"",S18+1),"") -> 82 | T19: =IFERROR(_xlfn.XLOOKUP(S19,'RMD Simulation'!AL:AL,'RMD Simulation'!AS:AS),"") -> 27058.197 | U19: =IFERROR(_xlfn.XLOOKUP(S19,'RMD Simulation'!AA:AA,'RMD Simulation'!AH:AH),"") -> 22980.562 | V19: =IFERROR(_xlfn.XLOOKUP(S19,'RMD Simulation'!P:P,'RMD Simulation'!W:W),"") -> 23918.278
E20: Total Cash Outlay | F20: =SUM(F13:F19) -> 244395.42 | G20: =SUM(G13:G19) -> 228813.35 | H20: =SUM(H13:H19) -> 232842.87 | I20: =SUM(I13:I19) -> 236623.66 | J20: =SUM(J13:J19) -> 235231.11 | K20: =SUM(K13:K19) -> 251167.1 | L20: =SUM(L13:L19) -> 236623.66 | S20: =IFERROR(IF(S19+1>99,"",S19+1),"") -> 83 | T20: =IFERROR(_xlfn.XLOOKUP(S20,'RMD Simulation'!AL:AL,'RMD Simulation'!AS:AS),"") -> 28625.127 | U20: =IFERROR(_xlfn.XLOOKUP(S20,'RMD Simulation'!AA:AA,'RMD Simulation'!AH:AH),"") -> 24311.357 | V20: =IFERROR(_xlfn.XLOOKUP(S20,'RMD Simulation'!P:P,'RMD Simulation'!W:W),"") -> 25303.376
E21: Savings | F21: 0 | G21: =$F20-G20 -> 15582.066 | H21: =$F20-H20 -> 11552.554 | I21: =$F20-I20 -> 7771.76 | J21: =$F20-J20 -> 9164.3082 | K21: =$F20-K20+K18 -> -14331.68 | L21: =F20-L20+L18 -> 7771.76 | S21: =IFERROR(IF(S20+1>99,"",S20+1),"") -> 84 | T21: =IFERROR(_xlfn.XLOOKUP(S21,'RMD Simulation'!AL:AL,'RMD Simulation'!AS:AS),"") -> 30446.571 | U21: =IFERROR(_xlfn.XLOOKUP(S21,'RMD Simulation'!AA:AA,'RMD Simulation'!AH:AH),"") -> 25858.312 | V21: =IFERROR(_xlfn.XLOOKUP(S21,'RMD Simulation'!P:P,'RMD Simulation'!W:W),"") -> 26913.453
E22: Effective Tax Rate | F22: =($F$20-F21)/('No planning'!$C$15+$C$2) -> 0.28752402 | G22: =($F$20-G21)/('No planning'!$C$15+$C$2) -> 0.26919218 | H22: =($F$20-H21)/('No planning'!$C$15+$C$2) -> 0.27393278 | I22: =($F$20-I21)/('No planning'!$C$15+$C$2) -> 0.27838078 | J22: =($F$20-J21)/('No planning'!$C$15+$C$2) -> 0.27674248 | K22: =($F$20-K21)/('No planning'!$C$15+$C$2) -> 0.30438482 | L22: =($F$20-L21)/('No planning'!$C$15+$C$2) -> 0.27838078 | S22: =IFERROR(IF(S21+1>99,"",S21+1),"") -> 85 | T22: =IFERROR(_xlfn.XLOOKUP(S22,'RMD Simulation'!AL:AL,'RMD Simulation'!AS:AS),"") -> 32170.608 | U22: =IFERROR(_xlfn.XLOOKUP(S22,'RMD Simulation'!AA:AA,'RMD Simulation'!AH:AH),"") -> 27322.539 | V22: =IFERROR(_xlfn.XLOOKUP(S22,'RMD Simulation'!P:P,'RMD Simulation'!W:W),"") -> 28437.428
S23: =IFERROR(IF(S22+1>99,"",S22+1),"") -> 86 | T23: =IFERROR(_xlfn.XLOOKUP(S23,'RMD Simulation'!AL:AL,'RMD Simulation'!AS:AS),"") -> 33969.622 | U23: =IFERROR(_xlfn.XLOOKUP(S23,'RMD Simulation'!AA:AA,'RMD Simulation'!AH:AH),"") -> 28850.444 | V23: =IFERROR(_xlfn.XLOOKUP(S23,'RMD Simulation'!P:P,'RMD Simulation'!W:W),"") -> 30027.679
S24: =IFERROR(IF(S23+1>99,"",S23+1),"") -> 87 | T24: =IFERROR(_xlfn.XLOOKUP(S24,'RMD Simulation'!AL:AL,'RMD Simulation'!AS:AS),"") -> 35842.67 | U24: =IFERROR(_xlfn.XLOOKUP(S24,'RMD Simulation'!AA:AA,'RMD Simulation'!AH:AH),"") -> 30441.225 | V24: =IFERROR(_xlfn.XLOOKUP(S24,'RMD Simulation'!P:P,'RMD Simulation'!W:W),"") -> 31683.371
S25: =IFERROR(IF(S24+1>99,"",S24+1),"") -> 88 | T25: =IFERROR(_xlfn.XLOOKUP(S25,'RMD Simulation'!AL:AL,'RMD Simulation'!AS:AS),"") -> 37511.839 | U25: =IFERROR(_xlfn.XLOOKUP(S25,'RMD Simulation'!AA:AA,'RMD Simulation'!AH:AH),"") -> 31858.853 | V25: =IFERROR(_xlfn.XLOOKUP(S25,'RMD Simulation'!P:P,'RMD Simulation'!W:W),"") -> 33158.845
E26: Roth Conversion | S26: =IFERROR(IF(S25+1>99,"",S25+1),"") -> 89 | T26: =IFERROR(_xlfn.XLOOKUP(S26,'RMD Simulation'!AL:AL,'RMD Simulation'!AS:AS),"") -> 39515.379 | U26: =IFERROR(_xlfn.XLOOKUP(S26,'RMD Simulation'!AA:AA,'RMD Simulation'!AH:AH),"") -> 33560.461 | V26: =IFERROR(_xlfn.XLOOKUP(S26,'RMD Simulation'!P:P,'RMD Simulation'!W:W),"") -> 34929.887
F27: No Planning | G27: Film | H27: Solar | I27: Charitable | J27: Solar & Charitable | K27: LEAP | L27: LEAP & Charitable | S27: =IFERROR(IF(S26+1>99,"",S26+1),"") -> 90 | T27: =IFERROR(_xlfn.XLOOKUP(S27,'RMD Simulation'!AL:AL,'RMD Simulation'!AS:AS),"") -> 41241.747 | U27: =IFERROR(_xlfn.XLOOKUP(S27,'RMD Simulation'!AA:AA,'RMD Simulation'!AH:AH),"") -> 35026.669 | V27: =IFERROR(_xlfn.XLOOKUP(S27,'RMD Simulation'!P:P,'RMD Simulation'!W:W),"") -> 36455.923
E28: Fed Ordinary Income Tax | F28: ='Roth only'!C19 -> 236662.88 | G28: ='Film & Roth'!C22 -> 0 | H28: =MIN('Solar & Roth'!C20, F28) -> 0 | I28: ='Charitable & Roth'!C22 -> 88911.1 | J28: =MIN('Solar & Charitable & Roth'!C25,'Solar & Charitable & Roth'!C58) -> 0 | K28: ='LEAP & Roth'!C28 -> 236662.88 | L28: ='LEAP & Charitable & Roth'!C63 -> 88911.1 | S28: =IFERROR(IF(S27+1>99,"",S27+1),"") -> 91 | T28: =IFERROR(_xlfn.XLOOKUP(S28,'RMD Simulation'!AL:AL,'RMD Simulation'!AS:AS),"") -> 42977.487 | U28: =IFERROR(_xlfn.XLOOKUP(S28,'RMD Simulation'!AA:AA,'RMD Simulation'!AH:AH),"") -> 36500.834 | V28: =IFERROR(_xlfn.XLOOKUP(S28,'RMD Simulation'!P:P,'RMD Simulation'!W:W),"") -> 37990.242
E29: Fed LTCG Tax | F29: ='Roth only'!C20 -> 0 | G29: ='Film & Roth'!C24 -> 0 | H29: =MIN(MAX('Solar & Roth'!C20 - H28, 0), F29) -> 0 | I29: ='Charitable & Roth'!C24 -> 0 | J29: =MIN(MAX('Solar & Charitable & Roth'!C58-J28,0),'Solar & Charitable & Roth'!C27) -> 0 | K29: ='LEAP & Roth'!J28 -> 0 | L29: ='LEAP & Charitable & Roth'!C65 -> 0 | S29: =IFERROR(IF(S28+1>99,"",S28+1),"") -> 92 | T29: =IFERROR(_xlfn.XLOOKUP(S29,'RMD Simulation'!AL:AL,'RMD Simulation'!AS:AS),"") -> 44708.524 | U29: =IFERROR(_xlfn.XLOOKUP(S29,'RMD Simulation'!AA:AA,'RMD Simulation'!AH:AH),"") -> 37971.007 | V29: =IFERROR(_xlfn.XLOOKUP(S29,'RMD Simulation'!P:P,'RMD Simulation'!W:W),"") -> 39520.404
E30: State Tax | F30: ='Roth only'!C21 -> 25500 | G30: ='Film & Roth'!I42 -> 0 | H30: ='Solar & Roth'!J42 -> 22811.802 | I30: ='Charitable & Roth'!H42 -> 25500 | J30: ='Solar & Charitable & Roth'!J42 -> 24450.752 | K30: ='LEAP & Roth'!C29 -> 25500 | L30: ='LEAP & Charitable & Roth'!C64 -> 25500 | S30: =IFERROR(IF(S29+1>99,"",S29+1),"") -> 93 | T30: =IFERROR(_xlfn.XLOOKUP(S30,'RMD Simulation'!AL:AL,'RMD Simulation'!AS:AS),"") -> 46417.187 | U30: =IFERROR(_xlfn.XLOOKUP(S30,'RMD Simulation'!AA:AA,'RMD Simulation'!AH:AH),"") -> 39422.176 | V30: =IFERROR(_xlfn.XLOOKUP(S30,'RMD Simulation'!P:P,'RMD Simulation'!W:W),"") -> 41030.788
E31: Strategy Contribution | F31: 0 | G31: ='Film & Roth'!D14 -> 178947.37 | H31: ='Solar & Roth'!C18 -> 201426.72 | I31: ='Charitable & Roth'!D14 -> 85000 | J31: ='Solar & Charitable & Roth'!D17+'Solar & Charitable & Roth'!C49 -> 163613.21 | K31: ='LEAP & Roth'!D14+'LEAP & Roth'!E14+'LEAP & Roth'!D12+'LEAP & Roth'!E12 -> 0 | L31: ='LEAP & Charitable & Roth'!C78-L19 -> 85000 | S31: =IFERROR(IF(S30+1>99,"",S30+1),"") -> 94 | T31: =IFERROR(_xlfn.XLOOKUP(S31,'RMD Simulation'!AL:AL,'RMD Simulation'!AS:AS),"") -> 47575.174 | U31: =IFERROR(_xlfn.XLOOKUP(S31,'RMD Simulation'!AA:AA,'RMD Simulation'!AH:AH),"") -> 40405.656 | V31: =IFERROR(_xlfn.XLOOKUP(S31,'RMD Simulation'!P:P,'RMD Simulation'!W:W),"") -> 42054.398
E32: Investment Account | F32: 0 | G32: 0 | H32: 0 | I32: 0 | J32: 0 | K32: ='LEAP & Roth'!D20+'LEAP & Roth'!E20 -> 0 | L32: ='LEAP & Charitable & Roth'!C79 -> 0 | S32: =IFERROR(IF(S31+1>99,"",S31+1),"") -> 95 | T32: =IFERROR(_xlfn.XLOOKUP(S32,'RMD Simulation'!AL:AL,'RMD Simulation'!AS:AS),"") -> 48617.551 | U32: =IFERROR(_xlfn.XLOOKUP(S32,'RMD Simulation'!AA:AA,'RMD Simulation'!AH:AH),"") -> 41290.948 | V32: =IFERROR(_xlfn.XLOOKUP(S32,'RMD Simulation'!P:P,'RMD Simulation'!W:W),"") -> 42975.815
E33: Membership Fee | F33: ='Strategy comparison'!$C$12 -> 0 | G33: ='Film & Roth'!D16 -> 0 | H33: ='Strategy comparison'!C12 -> 0 | I33: ='Strategy comparison'!C12 -> 0 | J33: ='Strategy comparison'!C12 -> 0 | K33: ='Strategy comparison'!C12 -> 0 | L33: ='Strategy comparison'!C12 -> 0 | S33: =IFERROR(IF(S32+1>99,"",S32+1),"") -> 96 | T33: =IFERROR(_xlfn.XLOOKUP(S33,'RMD Simulation'!AL:AL,'RMD Simulation'!AS:AS),"") -> 48924.305 | U33: =IFERROR(_xlfn.XLOOKUP(S33,'RMD Simulation'!AA:AA,'RMD Simulation'!AH:AH),"") -> 41551.474 | V33: =IFERROR(_xlfn.XLOOKUP(S33,'RMD Simulation'!P:P,'RMD Simulation'!W:W),"") -> 43246.971
E34: Total Cash Outlay | F34: =SUM(F28:F33) -> 262162.88 | G34: =SUM(G28:G33) -> 178947.37 | H34: =SUM(H28:H33) -> 224238.52 | I34: =SUM(I28:I33) -> 199411.1 | J34: =SUM(J28:J33) -> 188063.96 | K34: =SUM(K28:K33) -> 262162.88 | L34: =SUM(L28:L33) -> 199411.1 | S34: =IFERROR(IF(S33+1>99,"",S33+1),"") -> 97 | T34: =IFERROR(_xlfn.XLOOKUP(S34,'RMD Simulation'!AL:AL,'RMD Simulation'!AS:AS),"") -> 49664.441 | U34: =IFERROR(_xlfn.XLOOKUP(S34,'RMD Simulation'!AA:AA,'RMD Simulation'!AH:AH),"") -> 42180.074 | V34: =IFERROR(_xlfn.XLOOKUP(S34,'RMD Simulation'!P:P,'RMD Simulation'!W:W),"") -> 43901.221
E35: Savings | F35: =$F20-F34 -> -17767.46 | G35: =$F20-G34 -> 65448.052 | H35: =$F20-H34 -> 20156.896 | I35: =$F20-I34 -> 44984.32 | J35: =$F20-J34 -> 56331.459 | K35: =$F20-K34+K32 -> -17767.46 | L35: =$F20-L34+L32 -> 44984.32 | S35: =IFERROR(IF(S34+1>99,"",S34+1),"") -> 98 | T35: =IFERROR(_xlfn.XLOOKUP(S35,'RMD Simulation'!AL:AL,'RMD Simulation'!AS:AS),"") -> 49501.161 | U35: =IFERROR(_xlfn.XLOOKUP(S35,'RMD Simulation'!AA:AA,'RMD Simulation'!AH:AH),"") -> 42041.399 | V35: =IFERROR(_xlfn.XLOOKUP(S35,'RMD Simulation'!P:P,'RMD Simulation'!W:W),"") -> 43756.888
E36: Effective Tax Rate | F36: =($F$20-F35)/('No planning'!$C$15+$C$2) -> 0.30842692 | G36: =($F$20-G35)/('No planning'!$C$15+$C$2) -> 0.21052632 | H36: =($F$20-H35)/('No planning'!$C$15+$C$2) -> 0.26381003 | I36: =($F$20-I35)/('No planning'!$C$15+$C$2) -> 0.23460129 | J36: =($F$20-J35)/('No planning'!$C$15+$C$2) -> 0.22125172 | K36: =($F$20-K35)/('No planning'!$C$15+$C$2) -> 0.30842692 | L36: =($F$20-L35)/('No planning'!$C$15+$C$2) -> 0.23460129 | S36: =IFERROR(IF(S35+1>99,"",S35+1),"") -> 99 | T36: =IFERROR(_xlfn.XLOOKUP(S36,'RMD Simulation'!AL:AL,'RMD Simulation'!AS:AS),"") -> 49071.666 | U36: =IFERROR(_xlfn.XLOOKUP(S36,'RMD Simulation'!AA:AA,'RMD Simulation'!AH:AH),"") -> 41676.628 | V36: =IFERROR(_xlfn.XLOOKUP(S36,'RMD Simulation'!P:P,'RMD Simulation'!W:W),"") -> 43377.232
S37: =IFERROR(IF(S36+1>99,"",S36+1),"") | U37: =IFERROR(_xlfn.XLOOKUP(S37,'RMD Simulation'!AA:AA,'RMD Simulation'!AH:AH),"") | V37: =IFERROR(_xlfn.XLOOKUP(S37,'RMD Simulation'!P:P,'RMD Simulation'!W:W),"")
S38: =IFERROR(IF(S37+1>99,"",S37+1),"") | U38: =IFERROR(_xlfn.XLOOKUP(S38,'RMD Simulation'!AA:AA,'RMD Simulation'!AH:AH),"") | V38: =IFERROR(_xlfn.XLOOKUP(S38,'RMD Simulation'!P:P,'RMD Simulation'!W:W),"")
E39: Net Savings | S39: =IFERROR(IF(S38+1>99,"",S38+1),"") | U39: =IFERROR(_xlfn.XLOOKUP(S39,'RMD Simulation'!AA:AA,'RMD Simulation'!AH:AH),"") | V39: =IFERROR(_xlfn.XLOOKUP(S39,'RMD Simulation'!P:P,'RMD Simulation'!W:W),"")
F40: No Planning | G40: Film | H40: Solar | I40: Charitable | J40: Solar & Charitable | K40: LEAP | L40: LEAP & Charitable | S40: =IFERROR(IF(S39+1>99,"",S39+1),"") | U40: =IFERROR(_xlfn.XLOOKUP(S40,'RMD Simulation'!AA:AA,'RMD Simulation'!AH:AH),"") | V40: =IFERROR(_xlfn.XLOOKUP(S40,'RMD Simulation'!P:P,'RMD Simulation'!W:W),"")
...

Sheet No planning
B4: Inputs | G4: Federal Ordinary Income Tax
B5: Filing Status - LA | C5: ='Strategy comparison'!C4 -> Married-Joint
B6: W2 Income | C6: ='Strategy comparison'!C5 -> 400000 | G6: Married Filing Joint | J6: Ordinary Income | K6: Non-LTCG AGI w Gift | M6: Unmarried/Single | P6: Ordinary Income | Q6: Non-LTCG AGI w Gift
B7: Business Income | C7: ='Strategy comparison'!C6 -> 0 | J7: =C12 -> 400000 | K7: =J7-MIN(C15*#REF!,J7) -> #REF! | P7: =J7 -> 400000 | Q7: =K7 -> #REF!
B8: ST Capital Gains | C8: ='Strategy comparison'!C7 -> 0 | G8: ='Tax Tables'!B6 -> 0 | H8: ='Tax Tables'!C6 -> 24800 | I8: ='Tax Tables'!D6 -> 0.1 | J8: =IF(IF(J$7>H8,(H8-G8)*I8,(J$7-G8)*I8)>0,IF(J$7>H8,(H8-G8)*I8,(J$7-G8)*I8),0) -> 2480 | K8: =IF(IF(K$7>H8,(H8-G8)*I8,(K$7-G8)*I8)>0,IF(K$7>H8,(H8-G8)*I8,(K$7-G8)*I8),0) -> #REF! | M8: ='Tax Tables'!F6 -> 0 | N8: ='Tax Tables'!G6 -> 12400 | O8: ='Tax Tables'!H6 -> 0.1 | P8: =IF(IF(P$7>N8,(N8-M8)*O8,(P$7-M8)*O8)>0,IF(P$7>N8,(N8-M8)*O8,(P$7-M8)*O8),0) -> 1240 | Q8: =IF(IF(Q$7>N8,(N8-M8)*O8,(Q$7-M8)*O8)>0,IF(Q$7>N8,(N8-M8)*O8,(Q$7-M8)*O8),0) -> #REF!
B9: Interest | C9: ='Strategy comparison'!$C$9 -> 0 | G9: ='Tax Tables'!B7 -> 24801 | H9: ='Tax Tables'!C7 -> 100800 | I9: ='Tax Tables'!D7 -> 0.12 | J9: =IF(IF(J$7>H9,(H9-G9)*I9,(J$7-G9)*I9)>0,IF(J$7>H9,(H9-G9)*I9,(J$7-G9)*I9),0) -> 9119.88 | K9: =IF(IF(K$7>H9,(H9-G9)*I9,(K$7-G9)*I9)>0,IF(K$7>H9,(H9-G9)*I9,(K$7-G9)*I9),0) -> #REF! | M9: ='Tax Tables'!F7 -> 12401 | N9: ='Tax Tables'!G7 -> 50400 | O9: ='Tax Tables'!H7 -> 0.12 | P9: =IF(IF(P$7>N9,(N9-M9)*O9,(P$7-M9)*O9)>0,IF(P$7>N9,(N9-M9)*O9,(P$7-M9)*O9),0) -> 4559.88 | Q9: =IF(IF(Q$7>N9,(N9-M9)*O9,(Q$7-M9)*O9)>0,IF(Q$7>N9,(N9-M9)*O9,(Q$7-M9)*O9),0) -> #REF!
B10: Qualified Dividends | C10: ='Strategy comparison'!$C$10 -> 0 | G10: ='Tax Tables'!B8 -> 100801 | H10: ='Tax Tables'!C8 -> 211400 | I10: ='Tax Tables'!D8 -> 0.22 | J10: =IF(IF(J$7>H10,(H10-G10)*I10,(J$7-G10)*I10)>0,IF(J$7>H10,(H10-G10)*I10,(J$7-G10)*I10),0) -> 24331.78 | K10: =IF(IF(K$7>H10,(H10-G10)*I10,(K$7-G10)*I10)>0,IF(K$7>H10,(H10-G10)*I10,(K$7-G10)*I10),0) -> #REF! | M10: ='Tax Tables'!F8 -> 50401 | N10: ='Tax Tables'!G8 -> 105700 | O10: ='Tax Tables'!H8 -> 0.22 | P10: =IF(IF(P$7>N10,(N10-M10)*O10,(P$7-M10)*O10)>0,IF(P$7>N10,(N10-M10)*O10,(P$7-M10)*O10),0) -> 12165.78 | Q10: =IF(IF(Q$7>N10,(N10-M10)*O10,(Q$7-M10)*O10)>0,IF(Q$7>N10,(N10-M10)*O10,(Q$7-M10)*O10),0) -> #REF!
B11: Nonqualified Dividends | C11: ='Strategy comparison'!$C$11 -> 0 | G11: ='Tax Tables'!B9 -> 211401 | H11: ='Tax Tables'!C9 -> 403550 | I11: ='Tax Tables'!D9 -> 0.24 | J11: =IF(IF(J$7>H11,(H11-G11)*I11,(J$7-G11)*I11)>0,IF(J$7>H11,(H11-G11)*I11,(J$7-G11)*I11),0) -> 45263.76 | K11: =IF(IF(K$7>H11,(H11-G11)*I11,(K$7-G11)*I11)>0,IF(K$7>H11,(H11-G11)*I11,(K$7-G11)*I11),0) -> #REF! | M11: ='Tax Tables'!F9 -> 105701 | N11: ='Tax Tables'!G9 -> 201775 | O11: ='Tax Tables'!H9 -> 0.24 | P11: =IF(IF(P$7>N11,(N11-M11)*O11,(P$7-M11)*O11)>0,IF(P$7>N11,(N11-M11)*O11,(P$7-M11)*O11),0) -> 23057.76 | Q11: =IF(IF(Q$7>N11,(N11-M11)*O11,(Q$7-M11)*O11)>0,IF(Q$7>N11,(N11-M11)*O11,(Q$7-M11)*O11),0) -> #REF!
B12: Ordinary Income | C12: =SUM(C6:C9)+C11 -> 400000 | G12: ='Tax Tables'!B10 -> 403551 | H12: ='Tax Tables'!C10 -> 512450 | I12: ='Tax Tables'!D10 -> 0.32 | J12: =IF(IF(J$7>H12,(H12-G12)*I12,(J$7-G12)*I12)>0,IF(J$7>H12,(H12-G12)*I12,(J$7-G12)*I12),0) -> 0 | K12: =IF(IF(K$7>H12,(H12-G12)*I12,(K$7-G12)*I12)>0,IF(K$7>H12,(H12-G12)*I12,(K$7-G12)*I12),0) -> #REF! | M12: ='Tax Tables'!F10 -> 201776 | N12: ='Tax Tables'!G10 -> 256225 | O12: ='Tax Tables'!H10 -> 0.32 | P12: =IF(IF(P$7>N12,(N12-M12)*O12,(P$7-M12)*O12)>0,IF(P$7>N12,(N12-M12)*O12,(P$7-M12)*O12),0) -> 17423.68 | Q12: =IF(IF(Q$7>N12,(N12-M12)*O12,(Q$7-M12)*O12)>0,IF(Q$7>N12,(N12-M12)*O12,(Q$7-M12)*O12),0) -> #REF!
B13: LTCG | C13: ='Strategy comparison'!C8 -> 0 | G13: ='Tax Tables'!B11 -> 512451 | H13: ='Tax Tables'!C11 -> 768700 | I13: ='Tax Tables'!D11 -> 0.35 | J13: =IF(IF(J$7>H13,(H13-G13)*I13,(J$7-G13)*I13)>0,IF(J$7>H13,(H13-G13)*I13,(J$7-G13)*I13),0) -> 0 | K13: =IF(IF(K$7>H13,(H13-G13)*I13,(K$7-G13)*I13)>0,IF(K$7>H13,(H13-G13)*I13,(K$7-G13)*I13),0) -> #REF! | M13: ='Tax Tables'!F11 -> 256226 | N13: ='Tax Tables'!G11 -> 640600 | O13: ='Tax Tables'!H11 -> 0.35 | P13: =IF(IF(P$7>N13,(N13-M13)*O13,(P$7-M13)*O13)>0,IF(P$7>N13,(N13-M13)*O13,(P$7-M13)*O13),0) -> 50320.9 | Q13: =IF(IF(Q$7>N13,(N13-M13)*O13,(Q$7-M13)*O13)>0,IF(Q$7>N13,(N13-M13)*O13,(Q$7-M13)*O13),0) -> #REF!
B14: LTCG & Qualified Dividends | C14: =C13+C10 -> 0 | G14: ='Tax Tables'!B12 -> 768701 | H14: ='Tax Tables'!C12 -> 99999999999 | I14: ='Tax Tables'!D12 -> 0.37 | J14: =IF(J7>=G14,(J7-G14)*I14,0) -> 0 | K14: =IF(K7>=G14,(K7-G14)*I14,0) -> #REF! | M14: ='Tax Tables'!F12 -> 640601 | N14: ='Tax Tables'!G12 -> 99999999999 | O14: ='Tax Tables'!H12 -> 0.37 | P14: =IF(P7>=M14,(P7-M14)*O14,0) -> 0 | Q14: =IF(Q7>=M14,(Q7-M14)*O14,0) -> #REF!
B15: AGI | C15: =C12+C14 -> 400000
I16: Est. Tax Expense | K16: Difference | O16: Est. Tax Expense | Q16: Difference
I17: =SUM(J8:J14) -> 81195.42 | J17: =SUM(K8:K14) -> #REF! | K17: =I17-J17 -> #REF! | O17: =SUM(P8:P14) -> 108768 | P17: =SUM(Q8:Q14) -> #REF! | Q17: =O17-P17 -> #REF!
B18: Summary
B19: Fed Ord. Income Tax | C19: =IF(C5="Married-Joint", I17,O17) -> 81195.42 | G19: Long Term Capital Gains & Qualified Dividends Tax
B20: Fed LTCG & QD Tax | C20: =IF(C5="Married-Joint", I28,O28) -> 0
B21: State Tax | C21: =I42 -> 12000 | G21: Married Filing Joint | J21: LTCG & QD | K21: AGI w Gift | M21: Unmarried/Single | P21: LTCG & QD | Q21: AGI w Gift
B22: NIIT | C22: =I45 -> 5700 | J22: =C14 -> 0 | K22: =J22-IF((#REF!*#REF!)>J7, (#REF!*#REF!)-J7,0) -> #REF! | P22: =J22 -> 0 | Q22: =P22-IF((#REF!*#REF!)>P7, (#REF!*#REF!)-P7,0) -> #REF!
B23: Total | C23: =SUM(C19:C22) -> 98895.42 | G23: ='Tax Tables'!B18 -> 0 | H23: ='Tax Tables'!C18 -> 98900 | I23: ='Tax Tables'!D18 -> 0 | J23: =IF(J$22>$H23,($H23-$G23)*$I23,MAX((J$22-$G23),0)*$I23) -> 0 | K23: =IF(K$22>$H23,($H23-$G23)*$I23,MAX((K$22-$G23),0)*$I23) -> #REF! | M23: ='Tax Tables'!F18 -> 0 | N23: ='Tax Tables'!G18 -> 49450 | O23: ='Tax Tables'!H18 -> 0 | P23: =IF(P$22>$N23,($N23-$M23)*$O23,MAX((P$22-$M23),0)*$O23) -> 0 | Q23: =IF(Q$22>$N23,($N23-$M23)*$O23,MAX((Q$22-$M23),0)*$O23) -> #REF!
G24: ='Tax Tables'!B19 -> 98901 | H24: ='Tax Tables'!C19 -> 613700 | I24: ='Tax Tables'!D19 -> 0.15 | J24: =IF(J$22>$H24,($H24-$G24)*$I24,MAX((J$22-$G24),0)*$I24) -> 0 | K24: =IF(K$22>$H24,($H24-$G24)*$I24,MAX((K$22-$G24),0)*$I24) -> #REF! | M24: ='Tax Tables'!F19 -> 49451 | N24: ='Tax Tables'!G19 -> 545500 | O24: ='Tax Tables'!H19 -> 0.15 | P24: =IF(P$22>$N24,($N24-$M24)*$O24,MAX((P$22-$M24),0)*$O24) -> 0 | Q24: =IF(Q$22>$N24,($N24-$M24)*$O24,MAX((Q$22-$M24),0)*$O24) -> #REF!
G25: ='Tax Tables'!B20 -> 613701 | H25: ='Tax Tables'!C20 -> 99999999999 | I25: ='Tax Tables'!D20 -> 0.2 | J25: =IF(J$22>$H25,($H25-$G25)*$I25,MAX((J$22-$G25),0)*$I25) -> 0 | K25: =IF(K$22>$H25,($H25-$G25)*$I25,MAX((K$22-$G25),0)*$I25) -> #REF! | M25: ='Tax Tables'!F20 -> 545501 | N25: ='Tax Tables'!G20 -> 99999999999 | O25: ='Tax Tables'!H20 -> 0.2 | P25: =IF(P$22>$N25,($N25-$M25)*$O25,MAX((P$22-$M25),0)*$O25) -> 0 | Q25: =IF(Q$22>$N25,($N25-$M25)*$O25,MAX((Q$22-$M25),0)*$O25) -> #REF!
I27: Est. Tax Expense | K27: Difference | O27: Est. Tax Expense | Q27: Difference
I28: =SUM(J23:J25) -> 0 | J28: =SUM(K23:K25) -> #REF! | K28: =I28-J28 -> #REF! | O28: =SUM(P23:P25) -> 0 | P28: =SUM(Q23:Q25) -> #REF! | Q28: =O28-P28 -> #REF!
G30: State Income Tax - Louisiana
G32: Married Filing Joint | J32: AGI | K32: AGI w Depreciation | M32: Unmarried/Single | P32: AGI | Q32: AGI w Depreciation
J33: =C15 -> 400000 | K33: =J33-#REF! -> #REF! | P33: =J33 -> 400000 | Q33: =P33-#REF! -> #REF!
G34: ='Tax Tables'!B25 -> 0 | H34: ='Tax Tables'!C25 -> 100000000 | I34: ='Tax Tables'!D25 -> 0.03 | J34: =IF(IF(J$33>H34,(H34-G34)*I34,(J$33-G34)*I34)>0,IF(J$33>H34,(H34-G34)*I34,(J$33-G34)*I34),0) -> 12000 | K34: =IF(IF(K$33>H34,(H34-G34)*I34,(K$33-G34)*I34)>0,IF(K$33>H34,(H34-G34)*I34,(K$33-G34)*I34),0) -> #REF! | M34: ='Tax Tables'!F25 -> 0 | N34: ='Tax Tables'!G25 -> 100000000 | O34: ='Tax Tables'!H25 -> 0.03 | P34: =IF(IF(P$33>N34,(N34-M34)*O34,(P$33-M34)*O34)>0,IF(P$33>N34,(N34-M34)*O34,(P$33-M34)*O34),0) -> 12000 | Q34: =IF(IF(Q$33>N34,(N34-M34)*O34,(Q$33-M34)*O34)>0,IF(Q$33>N34,(N34-M34)*O34,(Q$33-M34)*O34),0) -> #REF!
G35: ='Tax Tables'!B26 -> 0 | H35: ='Tax Tables'!C26 -> 0 | I35: ='Tax Tables'!D26 -> 0 | J35: =IF(IF(J$33>H35,(H35-G35)*I35,(J$33-G35)*I35)>0,IF(J$33>H35,(H35-G35)*I35,(J$33-G35)*I35),0) -> 0 | K35: =IF(IF(K$33>H35,(H35-G35)*I35,(K$33-G35)*I35)>0,IF(K$33>H35,(H35-G35)*I35,(K$33-G35)*I35),0) -> #REF! | M35: ='Tax Tables'!F26 -> 0 | N35: ='Tax Tables'!G26 -> 0 | O35: ='Tax Tables'!H26 -> 0 | P35: =IF(IF(P$33>N35,(N35-M35)*O35,(P$33-M35)*O35)>0,IF(P$33>N35,(N35-M35)*O35,(P$33-M35)*O35),0) -> 0 | Q35: =IF(IF(Q$33>N35,(N35-M35)*O35,(Q$33-M35)*O35)>0,IF(Q$33>N35,(N35-M35)*O35,(Q$33-M35)*O35),0) -> #REF!
G36: ='Tax Tables'!B27 -> 0 | H36: ='Tax Tables'!C27 -> 0 | I36: ='Tax Tables'!D27 -> 0 | J36: =IF(IF(J$33>H36,(H36-G36)*I36,(J$33-G36)*I36)>0,IF(J$33>H36,(H36-G36)*I36,(J$33-G36)*I36),0) -> 0 | K36: =IF(IF(K$33>H36,(H36-G36)*I36,(K$33-G36)*I36)>0,IF(K$33>H36,(H36-G36)*I36,(K$33-G36)*I36),0) -> #REF! | M36: ='Tax Tables'!F27 -> 0 | N36: ='Tax Tables'!G27 -> 0 | O36: ='Tax Tables'!H27 -> 0 | P36: =IF(IF(P$33>N36,(N36-M36)*O36,(P$33-M36)*O36)>0,IF(P$33>N36,(N36-M36)*O36,(P$33-M36)*O36),0) -> 0 | Q36: =IF(IF(Q$33>N36,(N36-M36)*O36,(Q$33-M36)*O36)>0,IF(Q$33>N36,(N36-M36)*O36,(Q$33-M36)*O36),0) -> #REF!
G37: ='Tax Tables'!B28 -> 0 | H37: ='Tax Tables'!C28 -> 0 | I37: ='Tax Tables'!D28 -> 0 | J37: =IF(IF(J$33>H37,(H37-G37)*I37,(J$33-G37)*I37)>0,IF(J$33>H37,(H37-G37)*I37,(J$33-G37)*I37),0) -> 0 | K37: =IF(IF(K$33>H37,(H37-G37)*I37,(K$33-G37)*I37)>0,IF(K$33>H37,(H37-G37)*I37,(K$33-G37)*I37),0) -> #REF! | M37: ='Tax Tables'!F28 -> 0 | N37: ='Tax Tables'!G28 -> 0 | O37: ='Tax Tables'!H28 -> 0 | P37: =IF(IF(P$33>N37,(N37-M37)*O37,(P$33-M37)*O37)>0,IF(P$33>N37,(N37-M37)*O37,(P$33-M37)*O37),0) -> 0 | Q37: =IF(IF(Q$33>N37,(N37-M37)*O37,(Q$33-M37)*O37)>0,IF(Q$33>N37,(N37-M37)*O37,(Q$33-M37)*O37),0) -> #REF!
G38: ='Tax Tables'!B29 -> 0 | H38: ='Tax Tables'!C29 -> 0 | I38: ='Tax Tables'!D29 -> 0 | J38: =IF(IF(J$33>H38,(H38-G38)*I38,(J$33-G38)*I38)>0,IF(J$33>H38,(H38-G38)*I38,(J$33-G38)*I38),0) -> 0 | K38: =IF(IF(K$33>H38,(H38-G38)*I38,(K$33-G38)*I38)>0,IF(K$33>H38,(H38-G38)*I38,(K$33-G38)*I38),0) -> #REF! | M38: ='Tax Tables'!F29 -> 0 | N38: ='Tax Tables'!G29 -> 0 | O38: ='Tax Tables'!H29 -> 0 | P38: =IF(IF(P$33>N38,(N38-M38)*O38,(P$33-M38)*O38)>0,IF(P$33>N38,(N38-M38)*O38,(P$33-M38)*O38),0) -> 0 | Q38: =IF(IF(Q$33>N38,(N38-M38)*O38,(Q$33-M38)*O38)>0,IF(Q$33>N38,(N38-M38)*O38,(Q$33-M38)*O38),0) -> #REF!
G39: ='Tax Tables'!B30 -> 0 | H39: ='Tax Tables'!C30 -> 0 | I39: ='Tax Tables'!D30 -> 0 | J39: =IF(J33>=G39,(J33-G39)*I39,0) -> 0 | K39: =IF(K33>=G39,(K33-G39)*I39,0) -> #REF! | M39: ='Tax Tables'!F30 -> 0 | N39: ='Tax Tables'!G30 -> 0 | O39: ='Tax Tables'!H30 -> 0 | P39: =IF(P33>=M39,(P33-M39)*O39,0) -> 0 | Q39: =IF(Q33>=M39,(Q33-M39)*O39,0) -> #REF!
I41: Est. Tax Expense | K41: Difference | O41: Est. Tax Expense | Q41: Difference
I42: =SUM(J34:J39) -> 12000 | J42: =SUM(K34:K39) -> #REF! | K42: =I42-J42 -> #REF! | O42: =SUM(P34:P39) -> 12000 | P42: =SUM(Q34:Q39) -> #REF! | Q42: =O42-P42 -> #REF!
H44: NIIT | I44: ='Tax Tables'!$C$34 -> 0.038
H45: =SUM(C8:C11)+C13 -> 0 | I45: =IF(C15-IF(C5="Married-Joint",250000,200000)>H45,(C15-IF(C5="Married-Joint",250000,200000))*I44, H45*I44) -> 5700

Sheet Roth only
B4: Inputs | G4: Federal Ordinary Income Tax
B5: Filing Status - LA | C5: ='Strategy comparison'!C4 -> Married-Joint
B6: W2 Income | C6: ='Strategy comparison'!C5+'Roth comparison'!C2 -> 850000 | G6: Married Filing Joint | J6: Ordinary Income | K6: Non-LTCG AGI w Gift | M6: Unmarried/Single | P6: Ordinary Income | Q6: Non-LTCG AGI w Gift
B7: Business Income | C7: ='Strategy comparison'!C6 -> 0 | J7: =C12 -> 850000 | K7: =J7-MIN(C15*#REF!,J7) -> #REF! | P7: =J7 -> 850000 | Q7: =K7 -> #REF!
B8: ST Capital Gains | C8: ='Strategy comparison'!C7 -> 0 | G8: ='Tax Tables'!B6 -> 0 | H8: ='Tax Tables'!C6 -> 24800 | I8: ='Tax Tables'!D6 -> 0.1 | J8: =IF(IF(J$7>H8,(H8-G8)*I8,(J$7-G8)*I8)>0,IF(J$7>H8,(H8-G8)*I8,(J$7-G8)*I8),0) -> 2480 | K8: =IF(IF(K$7>H8,(H8-G8)*I8,(K$7-G8)*I8)>0,IF(K$7>H8,(H8-G8)*I8,(K$7-G8)*I8),0) -> #REF! | M8: ='Tax Tables'!F6 -> 0 | N8: ='Tax Tables'!G6 -> 12400 | O8: ='Tax Tables'!H6 -> 0.1 | P8: =IF(IF(P$7>N8,(N8-M8)*O8,(P$7-M8)*O8)>0,IF(P$7>N8,(N8-M8)*O8,(P$7-M8)*O8),0) -> 1240 | Q8: =IF(IF(Q$7>N8,(N8-M8)*O8,(Q$7-M8)*O8)>0,IF(Q$7>N8,(N8-M8)*O8,(Q$7-M8)*O8),0) -> #REF!
B9: Interest | C9: ='Strategy comparison'!$C$9 -> 0 | G9: ='Tax Tables'!B7 -> 24801 | H9: ='Tax Tables'!C7 -> 100800 | I9: ='Tax Tables'!D7 -> 0.12 | J9: =IF(IF(J$7>H9,(H9-G9)*I9,(J$7-G9)*I9)>0,IF(J$7>H9,(H9-G9)*I9,(J$7-G9)*I9),0) -> 9119.88 | K9: =IF(IF(K$7>H9,(H9-G9)*I9,(K$7-G9)*I9)>0,IF(K$7>H9,(H9-G9)*I9,(K$7-G9)*I9),0) -> #REF! | M9: ='Tax Tables'!F7 -> 12401 | N9: ='Tax Tables'!G7 -> 50400 | O9: ='Tax Tables'!H7 -> 0.12 | P9: =IF(IF(P$7>N9,(N9-M9)*O9,(P$7-M9)*O9)>0,IF(P$7>N9,(N9-M9)*O9,(P$7-M9)*O9),0) -> 4559.88 | Q9: =IF(IF(Q$7>N9,(N9-M9)*O9,(Q$7-M9)*O9)>0,IF(Q$7>N9,(N9-M9)*O9,(Q$7-M9)*O9),0) -> #REF!
B10: Qualified Dividends | C10: ='Strategy comparison'!$C$10 -> 0 | G10: ='Tax Tables'!B8 -> 100801 | H10: ='Tax Tables'!C8 -> 211400 | I10: ='Tax Tables'!D8 -> 0.22 | J10: =IF(IF(J$7>H10,(H10-G10)*I10,(J$7-G10)*I10)>0,IF(J$7>H10,(H10-G10)*I10,(J$7-G10)*I10),0) -> 24331.78 | K10: =IF(IF(K$7>H10,(H10-G10)*I10,(K$7-G10)*I10)>0,IF(K$7>H10,(H10-G10)*I10,(K$7-G10)*I10),0) -> #REF! | M10: ='Tax Tables'!F8 -> 50401 | N10: ='Tax Tables'!G8 -> 105700 | O10: ='Tax Tables'!H8 -> 0.22 | P10: =IF(IF(P$7>N10,(N10-M10)*O10,(P$7-M10)*O10)>0,IF(P$7>N10,(N10-M10)*O10,(P$7-M10)*O10),0) -> 12165.78 | Q10: =IF(IF(Q$7>N10,(N10-M10)*O10,(Q$7-M10)*O10)>0,IF(Q$7>N10,(N10-M10)*O10,(Q$7-M10)*O10),0) -> #REF!
B11: Nonqualified Dividends | C11: ='Strategy comparison'!$C$11 -> 0 | G11: ='Tax Tables'!B9 -> 211401 | H11: ='Tax Tables'!C9 -> 403550 | I11: ='Tax Tables'!D9 -> 0.24 | J11: =IF(IF(J$7>H11,(H11-G11)*I11,(J$7-G11)*I11)>0,IF(J$7>H11,(H11-G11)*I11,(J$7-G11)*I11),0) -> 46115.76 | K11: =IF(IF(K$7>H11,(H11-G11)*I11,(K$7-G11)*I11)>0,IF(K$7>H11,(H11-G11)*I11,(K$7-G11)*I11),0) -> #REF! | M11: ='Tax Tables'!F9 -> 105701 | N11: ='Tax Tables'!G9 -> 201775 | O11: ='Tax Tables'!H9 -> 0.24 | P11: =IF(IF(P$7>N11,(N11-M11)*O11,(P$7-M11)*O11)>0,IF(P$7>N11,(N11-M11)*O11,(P$7-M11)*O11),0) -> 23057.76 | Q11: =IF(IF(Q$7>N11,(N11-M11)*O11,(Q$7-M11)*O11)>0,IF(Q$7>N11,(N11-M11)*O11,(Q$7-M11)*O11),0) -> #REF!
B12: Ordinary Income | C12: =SUM(C6:C9)+C11 -> 850000 | G12: ='Tax Tables'!B10 -> 403551 | H12: ='Tax Tables'!C10 -> 512450 | I12: ='Tax Tables'!D10 -> 0.32 | J12: =IF(IF(J$7>H12,(H12-G12)*I12,(J$7-G12)*I12)>0,IF(J$7>H12,(H12-G12)*I12,(J$7-G12)*I12),0) -> 34847.68 | K12: =IF(IF(K$7>H12,(H12-G12)*I12,(K$7-G12)*I12)>0,IF(K$7>H12,(H12-G12)*I12,(K$7-G12)*I12),0) -> #REF! | M12: ='Tax Tables'!F10 -> 201776 | N12: ='Tax Tables'!G10 -> 256225 | O12: ='Tax Tables'!H10 -> 0.32 | P12: =IF(IF(P$7>N12,(N12-M12)*O12,(P$7-M12)*O12)>0,IF(P$7>N12,(N12-M12)*O12,(P$7-M12)*O12),0) -> 17423.68 | Q12: =IF(IF(Q$7>N12,(N12-M12)*O12,(Q$7-M12)*O12)>0,IF(Q$7>N12,(N12-M12)*O12,(Q$7-M12)*O12),0) -> #REF!
B13: LTCG | C13: ='Strategy comparison'!C8 -> 0 | G13: ='Tax Tables'!B11 -> 512451 | H13: ='Tax Tables'!C11 -> 768700 | I13: ='Tax Tables'!D11 -> 0.35 | J13: =IF(IF(J$7>H13,(H13-G13)*I13,(J$7-G13)*I13)>0,IF(J$7>H13,(H13-G13)*I13,(J$7-G13)*I13),0) -> 89687.15 | K13: =IF(IF(K$7>H13,(H13-G13)*I13,(K$7-G13)*I13)>0,IF(K$7>H13,(H13-G13)*I13,(K$7-G13)*I13),0) -> #REF! | M13: ='Tax Tables'!F11 -> 256226 | N13: ='Tax Tables'!G11 -> 640600 | O13: ='Tax Tables'!H11 -> 0.35 | P13: =IF(IF(P$7>N13,(N13-M13)*O13,(P$7-M13)*O13)>0,IF(P$7>N13,(N13-M13)*O13,(P$7-M13)*O13),0) -> 134530.9 | Q13: =IF(IF(Q$7>N13,(N13-M13)*O13,(Q$7-M13)*O13)>0,IF(Q$7>N13,(N13-M13)*O13,(Q$7-M13)*O13),0) -> #REF!
B14: LTCG & Qualified Dividends | C14: =C13+C10 -> 0 | G14: ='Tax Tables'!B12 -> 768701 | H14: ='Tax Tables'!C12 -> 99999999999 | I14: ='Tax Tables'!D12 -> 0.37 | J14: =IF(J7>=G14,(J7-G14)*I14,0) -> 30080.63 | K14: =IF(K7>=G14,(K7-G14)*I14,0) -> #REF! | M14: ='Tax Tables'!F12 -> 640601 | N14: ='Tax Tables'!G12 -> 99999999999 | O14: ='Tax Tables'!H12 -> 0.37 | P14: =IF(P7>=M14,(P7-M14)*O14,0) -> 77477.63 | Q14: =IF(Q7>=M14,(Q7-M14)*O14,0) -> #REF!
B15: AGI | C15: =C12+C14 -> 850000
I16: Est. Tax Expense | K16: Difference | O16: Est. Tax Expense | Q16: Difference
I17: =SUM(J8:J14) -> 236662.88 | J17: =SUM(K8:K14) -> #REF! | K17: =I17-J17 -> #REF! | O17: =SUM(P8:P14) -> 270455.63 | P17: =SUM(Q8:Q14) -> #REF! | Q17: =O17-P17 -> #REF!
B18: Summary
B19: Fed Ord. Income Tax | C19: =IF(C5="Married-Joint", I17,O17) -> 236662.88 | G19: Long Term Capital Gains & Qualified Dividends Tax
B20: Fed LTCG & QD Tax | C20: =IF(C5="Married-Joint", I28,O28) -> 0
B21: State Tax | C21: =I42 -> 25500 | G21: Married Filing Joint | J21: LTCG & QD | K21: AGI w Gift | M21: Unmarried/Single | P21: LTCG & QD | Q21: AGI w Gift
B22: NIIT | C22: =I45 -> 22800 | J22: =C14 -> 0 | K22: =J22-IF((#REF!*#REF!)>J7, (#REF!*#REF!)-J7,0) -> #REF! | P22: =J22 -> 0 | Q22: =P22-IF((#REF!*#REF!)>P7, (#REF!*#REF!)-P7,0) -> #REF!
B23: Total | C23: =SUM(C19:C22) -> 284962.88 | G23: ='Tax Tables'!B18 -> 0 | H23: ='Tax Tables'!C18 -> 98900 | I23: ='Tax Tables'!D18 -> 0 | J23: =IF(J$22>$H23,($H23-$G23)*$I23,MAX((J$22-$G23),0)*$I23) -> 0 | K23: =IF(K$22>$H23,($H23-$G23)*$I23,MAX((K$22-$G23),0)*$I23) -> #REF! | M23: ='Tax Tables'!F18 -> 0 | N23: ='Tax Tables'!G18 -> 49450 | O23: ='Tax Tables'!H18 -> 0 | P23: =IF(P$22>$N23,($N23-$M23)*$O23,MAX((P$22-$M23),0)*$O23) -> 0 | Q23: =IF(Q$22>$N23,($N23-$M23)*$O23,MAX((Q$22-$M23),0)*$O23) -> #REF!
G24: ='Tax Tables'!B19 -> 98901 | H24: ='Tax Tables'!C19 -> 613700 | I24: ='Tax Tables'!D19 -> 0.15 | J24: =IF(J$22>$H24,($H24-$G24)*$I24,MAX((J$22-$G24),0)*$I24) -> 0 | K24: =IF(K$22>$H24,($H24-$G24)*$I24,MAX((K$22-$G24),0)*$I24) -> #REF! | M24: ='Tax Tables'!F19 -> 49451 | N24: ='Tax Tables'!G19 -> 545500 | O24: ='Tax Tables'!H19 -> 0.15 | P24: =IF(P$22>$N24,($N24-$M24)*$O24,MAX((P$22-$M24),0)*$O24) -> 0 | Q24: =IF(Q$22>$N24,($N24-$M24)*$O24,MAX((Q$22-$M24),0)*$O24) -> #REF!
G25: ='Tax Tables'!B20 -> 613701 | H25: ='Tax Tables'!C20 -> 99999999999 | I25: ='Tax Tables'!D20 -> 0.2 | J25: =IF(J$22>$H25,($H25-$G25)*$I25,MAX((J$22-$G25),0)*$I25) -> 0 | K25: =IF(K$22>$H25,($H25-$G25)*$I25,MAX((K$22-$G25),0)*$I25) -> #REF! | M25: ='Tax Tables'!F20 -> 545501 | N25: ='Tax Tables'!G20 -> 99999999999 | O25: ='Tax Tables'!H20 -> 0.2 | P25: =IF(P$22>$N25,($N25-$M25)*$O25,MAX((P$22-$M25),0)*$O25) -> 0 | Q25: =IF(Q$22>$N25,($N25-$M25)*$O25,MAX((Q$22-$M25),0)*$O25) -> #REF!
I27: Est. Tax Expense | K27: Difference | O27: Est. Tax Expense | Q27: Difference
I28: =SUM(J23:J25) -> 0 | J28: =SUM(K23:K25) -> #REF! | K28: =I28-J28 -> #REF! | O28: =SUM(P23:P25) -> 0 | P28: =SUM(Q23:Q25) -> #REF! | Q28: =O28-P28 -> #REF!
G30: State Income Tax - Louisiana
G32: Married Filing Joint | J32: AGI | K32: AGI w Depreciation | M32: Unmarried/Single | P32: AGI | Q32: AGI w Depreciation
J33: =C15 -> 850000 | K33: =J33-#REF! -> #REF! | P33: =J33 -> 850000 | Q33: =P33-#REF! -> #REF!
G34: ='Tax Tables'!B25 -> 0 | H34: ='Tax Tables'!C25 -> 100000000 | I34: ='Tax Tables'!D25 -> 0.03 | J34: =IF(IF(J$33>H34,(H34-G34)*I34,(J$33-G34)*I34)>0,IF(J$33>H34,(H34-G34)*I34,(J$33-G34)*I34),0) -> 25500 | K34: =IF(IF(K$33>H34,(H34-G34)*I34,(K$33-G34)*I34)>0,IF(K$33>H34,(H34-G34)*I34,(K$33-G34)*I34),0) -> #REF! | M34: ='Tax Tables'!F25 -> 0 | N34: ='Tax Tables'!G25 -> 100000000 | O34: ='Tax Tables'!H25 -> 0.03 | P34: =IF(IF(P$33>N34,(N34-M34)*O34,(P$33-M34)*O34)>0,IF(P$33>N34,(N34-M34)*O34,(P$33-M34)*O34),0) -> 25500 | Q34: =IF(IF(Q$33>N34,(N34-M34)*O34,(Q$33-M34)*O34)>0,IF(Q$33>N34,(N34-M34)*O34,(Q$33-M34)*O34),0) -> #REF!
G35: ='Tax Tables'!B26 -> 0 | H35: ='Tax Tables'!C26 -> 0 | I35: ='Tax Tables'!D26 -> 0 | J35: =IF(IF(J$33>H35,(H35-G35)*I35,(J$33-G35)*I35)>0,IF(J$33>H35,(H35-G35)*I35,(J$33-G35)*I35),0) -> 0 | K35: =IF(IF(K$33>H35,(H35-G35)*I35,(K$33-G35)*I35)>0,IF(K$33>H35,(H35-G35)*I35,(K$33-G35)*I35),0) -> #REF! | M35: ='Tax Tables'!F26 -> 0 | N35: ='Tax Tables'!G26 -> 0 | O35: ='Tax Tables'!H26 -> 0 | P35: =IF(IF(P$33>N35,(N35-M35)*O35,(P$33-M35)*O35)>0,IF(P$33>N35,(N35-M35)*O35,(P$33-M35)*O35),0) -> 0 | Q35: =IF(IF(Q$33>N35,(N35-M35)*O35,(Q$33-M35)*O35)>0,IF(Q$33>N35,(N35-M35)*O35,(Q$33-M35)*O35),0) -> #REF!
G36: ='Tax Tables'!B27 -> 0 | H36: ='Tax Tables'!C27 -> 0 | I36: ='Tax Tables'!D27 -> 0 | J36: =IF(IF(J$33>H36,(H36-G36)*I36,(J$33-G36)*I36)>0,IF(J$33>H36,(H36-G36)*I36,(J$33-G36)*I36),0) -> 0 | K36: =IF(IF(K$33>H36,(H36-G36)*I36,(K$33-G36)*I36)>0,IF(K$33>H36,(H36-G36)*I36,(K$33-G36)*I36),0) -> #REF! | M36: ='Tax Tables'!F27 -> 0 | N36: ='Tax Tables'!G27 -> 0 | O36: ='Tax Tables'!H27 -> 0 | P36: =IF(IF(P$33>N36,(N36-M36)*O36,(P$33-M36)*O36)>0,IF(P$33>N36,(N36-M36)*O36,(P$33-M36)*O36),0) -> 0 | Q36: =IF(IF(Q$33>N36,(N36-M36)*O36,(Q$33-M36)*O36)>0,IF(Q$33>N36,(N36-M36)*O36,(Q$33-M36)*O36),0) -> #REF!
G37: ='Tax Tables'!B28 -> 0 | H37: ='Tax Tables'!C28 -> 0 | I37: ='Tax Tables'!D28 -> 0 | J37: =IF(IF(J$33>H37,(H37-G37)*I37,(J$33-G37)*I37)>0,IF(J$33>H37,(H37-G37)*I37,(J$33-G37)*I37),0) -> 0 | K37: =IF(IF(K$33>H37,(H37-G37)*I37,(K$33-G37)*I37)>0,IF(K$33>H37,(H37-G37)*I37,(K$33-G37)*I37),0) -> #REF! | M37: ='Tax Tables'!F28 -> 0 | N37: ='Tax Tables'!G28 -> 0 | O37: ='Tax Tables'!H28 -> 0 | P37: =IF(IF(P$33>N37,(N37-M37)*O37,(P$33-M37)*O37)>0,IF(P$33>N37,(N37-M37)*O37,(P$33-M37)*O37),0) -> 0 | Q37: =IF(IF(Q$33>N37,(N37-M37)*O37,(Q$33-M37)*O37)>0,IF(Q$33>N37,(N37-M37)*O37,(Q$33-M37)*O37),0) -> #REF!
G38: ='Tax Tables'!B29 -> 0 | H38: ='Tax Tables'!C29 -> 0 | I38: ='Tax Tables'!D29 -> 0 | J38: =IF(IF(J$33>H38,(H38-G38)*I38,(J$33-G38)*I38)>0,IF(J$33>H38,(H38-G38)*I38,(J$33-G38)*I38),0) -> 0 | K38: =IF(IF(K$33>H38,(H38-G38)*I38,(K$33-G38)*I38)>0,IF(K$33>H38,(H38-G38)*I38,(K$33-G38)*I38),0) -> #REF! | M38: ='Tax Tables'!F29 -> 0 | N38: ='Tax Tables'!G29 -> 0 | O38: ='Tax Tables'!H29 -> 0 | P38: =IF(IF(P$33>N38,(N38-M38)*O38,(P$33-M38)*O38)>0,IF(P$33>N38,(N38-M38)*O38,(P$33-M38)*O38),0) -> 0 | Q38: =IF(IF(Q$33>N38,(N38-M38)*O38,(Q$33-M38)*O38)>0,IF(Q$33>N38,(N38-M38)*O38,(Q$33-M38)*O38),0) -> #REF!
G39: ='Tax Tables'!B30 -> 0 | H39: ='Tax Tables'!C30 -> 0 | I39: ='Tax Tables'!D30 -> 0 | J39: =IF(J33>=G39,(J33-G39)*I39,0) -> 0 | K39: =IF(K33>=G39,(K33-G39)*I39,0) -> #REF! | M39: ='Tax Tables'!F30 -> 0 | N39: ='Tax Tables'!G30 -> 0 | O39: ='Tax Tables'!H30 -> 0 | P39: =IF(P33>=M39,(P33-M39)*O39,0) -> 0 | Q39: =IF(Q33>=M39,(Q33-M39)*O39,0) -> #REF!
I41: Est. Tax Expense | K41: Difference | O41: Est. Tax Expense | Q41: Difference
I42: =SUM(J34:J39) -> 25500 | J42: =SUM(K34:K39) -> #REF! | K42: =I42-J42 -> #REF! | O42: =SUM(P34:P39) -> 25500 | P42: =SUM(Q34:Q39) -> #REF! | Q42: =O42-P42 -> #REF!
H44: NIIT | I44: ='Tax Tables'!$C$34 -> 0.038
H45: =SUM(C8:C11)+C13 -> 0 | I45: =IF(C15-IF(C5="Married-Joint",250000,200000)>H45,(C15-IF(C5="Married-Joint",250000,200000))*I44, H45*I44) -> 22800

Sheet RMD Simulation
A1: Roth conversion calc (no savings) | P1: RMD calc | AA1: Roth calc (no tax savings) | AL1: Roth calc w/ Tax Savings
P2: Age | Q2: RMD % | R2: withdrawal rate | S2: non roth Account value (pre withdrawal) | T2: non roth Account value (post withdrawal) | U2: pre tax Income | V2: Incremental tax rate | W2: post tax income | X2: tax | Y2: taxable account | AA2: Age | AB2: RMD % | AC2: withdrawal rate | AD2: roth Account value (pre withdrawal) | AE2: roth Account value (post withdrawal) | AF2: pre tax Income | AG2: Incremental tax rate | AH2: post tax income | AI2: tax | AJ2: taxable account | AL2: Age | AM2: RMD % | AN2: withdrawal rate | AO2: roth Account value (pre withdrawal) | AP2: roth Account value (post withdrawal) | AQ2: pre tax Income | AR2: Incremental tax rate | AS2: post tax income | AT2: tax | AU2: taxable account
A3: Non Roth value | B3: ='Roth comparison'!C2 -> 450000 | P3: 35 | R3: =IF(P3<$B$9, 0, MAX(Q3,$B$10)) -> 0 | S3: =IF(P3=$B$4,$B$3,"") | T3: =IFERROR((1-R3)*S3,"") | U3: =IFERROR(R3*S3,0) -> 0 | V3: =$B$21 -> 0.35 | W3: =IF(P3<$B$4,0,(1-V3)*U3) -> 0 | X3: =IF(P3<$B$4,"",IF(P3=$B$4,"",IFERROR(U3*V3,0))) | Y3: =IF(W3>0, IF(Y2="",W3, (Y2*(1+$B$8)+W3)),"") | AA3: 35 | AC3: =IF(AA3<$B$9, 0, MAX(AB3,$B$10)) -> 0 | AD3: =IF(AA3=$B$4,$B$16,"") | AE3: =IFERROR((1-AC3)*AD3,"") | AF3: =IFERROR(AC3*AD3,0) -> 0 | AG3: 0 | AH3: =IF(AA3<$B$4,0,(1-AG3)*AF3) -> 0 | AI3: =IF(AA3=$B$4,$B$14,0) -> 0 | AJ3: =IF(AH3>0, IF(AJ2="",AH3, (AJ2*(1+$B$8)+AH3)),"") | AL3: 35 | AN3: =IF(AL3<$B$9, 0, MAX(AM3,$B$10)) -> 0 | AO3: =IF(AL3=$B$4,$B$16,"") | AP3: =IFERROR((1-AN3)*AO3,"") | AQ3: =IFERROR(AN3*AO3,0) -> 0 | AR3: 0 | AS3: =IF(AL3<$B$4,0,(1-AR3)*AQ3) -> 0 | AT3: =IF(AL3=$B$4,$B$14,0) -> 0 | AU3: =IF(AS3>0, IF(AU2="",AS3, (AU2*(1+$B$8)+AS3)),"")
A4: Age | B4: ='Roth comparison'!C3 -> 65 | D4: Federal Ordinary Income Tax | P4: 36 | R4: =IF(P4<$B$9, 0, MAX(Q4,$B$10)) -> 0 | S4: =IF(S3="",IF(P4=$B$4,$B$3,""),T3*(1+$B$8)) | T4: =IFERROR((1-R4)*S4,"") | U4: =IFERROR(R4*S4,0) -> 0 | V4: =$B$21 -> 0.35 | W4: =IF(P4<$B$4,0,(1-V4)*U4) -> 0 | X4: =IF(P4<$B$4,"",IF(P4=$B$4,"",IFERROR(U4*V4,0))) | Y4: =IF(W4>0, IF(Y3="",W4, (Y3*(1+$B$8)+W4)),"") | AA4: 36 | AC4: =IF(AA4<$B$9, 0, MAX(AB4,$B$10)) -> 0 | AD4: =IF(AA4=$B$4,$B$16,IF(AD3="","",AE3*(1+$B$8))) | AE4: =IFERROR((1-AC4)*AD4,"") | AF4: =IFERROR(AC4*AD4,0) -> 0 | AG4: 0 | AH4: =IF(AA4<$B$4,0,(1-AG4)*AF4) -> 0 | AI4: =IF(AA4=$B$4,$B$14,0) -> 0 | AJ4: =IF(AH4>0, IF(AJ3="",AH4, (AJ3*(1+$B$8)+AH4)),"") | AL4: 36 | AN4: =IF(AL4<$B$9, 0, MAX(AM4,$B$10)) -> 0 | AO4: =IF(AL4=$B$4,$B$16+$B$28,IF(AO3="","",AP3*(1+$B$8))) | AP4: =IFERROR((1-AN4)*AO4,"") | AQ4: =IFERROR(AN4*AO4,0) -> 0 | AR4: 0 | AS4: =IF(AL4<$B$4,0,(1-AR4)*AQ4) -> 0 | AT4: =IF(AL4=$B$4,$B$14,0) -> 0 | AU4: =IF(AS4>0, IF(AU3="",AS4, (AU3*(1+$B$8)+AS4)),"")
A5: Other income | B5: ='No planning'!C15 -> 400000 | P5: 37 | R5: =IF(P5<$B$9, 0, MAX(Q5,$B$10)) -> 0 | S5: =IF(S4="",IF(P5=$B$4,$B$3,""),T4*(1+$B$8)) | T5: =IFERROR((1-R5)*S5,"") | U5: =IFERROR(R5*S5,0) -> 0 | V5: =$B$21 -> 0.35 | W5: =IF(P5<$B$4,0,(1-V5)*U5) -> 0 | X5: =IF(P5<$B$4,"",IF(P5=$B$4,"",IFERROR(U5*V5,0))) | Y5: =IF(W5>0, IF(Y4="",W5, (Y4*(1+$B$8)+W5)),"") | AA5: 37 | AC5: =IF(AA5<$B$9, 0, MAX(AB5,$B$10)) -> 0 | AD5: =IF(AA5=$B$4,$B$16,IF(AD4="","",AE4*(1+$B$8))) | AE5: =IFERROR((1-AC5)*AD5,"") | AF5: =IFERROR(AC5*AD5,0) -> 0 | AG5: 0 | AH5: =IF(AA5<$B$4,0,(1-AG5)*AF5) -> 0 | AI5: =IF(AA5=$B$4,$B$14,0) -> 0 | AJ5: =IF(AH5>0, IF(AJ4="",AH5, (AJ4*(1+$B$8)+AH5)),"") | AL5: 37 | AN5: =IF(AL5<$B$9, 0, MAX(AM5,$B$10)) -> 0 | AO5: =IF(AL5=$B$4,$B$16+$B$28,IF(AO4="","",AP4*(1+$B$8))) | AP5: =IFERROR((1-AN5)*AO5,"") | AQ5: =IFERROR(AN5*AO5,0) -> 0 | AR5: 0 | AS5: =IF(AL5<$B$4,0,(1-AR5)*AQ5) -> 0 | AT5: =IF(AL5=$B$4,$B$14,0) -> 0 | AU5: =IF(AS5>0, IF(AU4="",AS5, (AU4*(1+$B$8)+AS5)),"")
A6: Total income | B6: =B3+B5 -> 850000 | D6: Married Filing Joint | G6: Total income | H6: Other income | J6: Unmarried/Single | M6: Ordinary Income | N6: Ordinary Income w Filn | P6: 38 | R6: =IF(P6<$B$9, 0, MAX(Q6,$B$10)) -> 0 | S6: =IF(S5="",IF(P6=$B$4,$B$3,""),T5*(1+$B$8)) | T6: =IFERROR((1-R6)*S6,"") | U6: =IFERROR(R6*S6,0) -> 0 | V6: =$B$21 -> 0.35 | W6: =IF(P6<$B$4,0,(1-V6)*U6) -> 0 | X6: =IF(P6<$B$4,"",IF(P6=$B$4,"",IFERROR(U6*V6,0))) | Y6: =IF(W6>0, IF(Y5="",W6, (Y5*(1+$B$8)+W6)),"") | AA6: 38 | AC6: =IF(AA6<$B$9, 0, MAX(AB6,$B$10)) -> 0 | AD6: =IF(AA6=$B$4,$B$16,IF(AD5="","",AE5*(1+$B$8))) | AE6: =IFERROR((1-AC6)*AD6,"") | AF6: =IFERROR(AC6*AD6,0) -> 0 | AG6: 0 | AH6: =IF(AA6<$B$4,0,(1-AG6)*AF6) -> 0 | AI6: =IF(AA6=$B$4,$B$14,0) -> 0 | AJ6: =IF(AH6>0, IF(AJ5="",AH6, (AJ5*(1+$B$8)+AH6)),"") | AL6: 38 | AN6: =IF(AL6<$B$9, 0, MAX(AM6,$B$10)) -> 0 | AO6: =IF(AL6=$B$4,$B$16+$B$28,IF(AO5="","",AP5*(1+$B$8))) | AP6: =IFERROR((1-AN6)*AO6,"") | AQ6: =IFERROR(AN6*AO6,0) -> 0 | AR6: 0 | AS6: =IF(AL6<$B$4,0,(1-AR6)*AQ6) -> 0 | AT6: =IF(AL6=$B$4,$B$14,0) -> 0 | AU6: =IF(AS6>0, IF(AU5="",AS6, (AU5*(1+$B$8)+AS6)),"")
